Traceback (most recent call last):
  File "C:\Users\AhmadYazidMunif\AppData\Local\Programs\Python\Python311\Lib\site-packages\jupyter_cache\executors\utils.py", line 58, in single_nb_execution
    executenb(
  File "C:\Users\AhmadYazidMunif\AppData\Local\Programs\Python\Python311\Lib\site-packages\nbclient\client.py", line 1204, in execute
    return NotebookClient(nb=nb, resources=resources, km=km, **kwargs).execute()
           ^^^^^^^^^^^^^^^^^^^^^^^^^^^^^^^^^^^^^^^^^^^^^^^^^^^^^^^^^^^^^^^^^^^^^
  File "C:\Users\AhmadYazidMunif\AppData\Local\Programs\Python\Python311\Lib\site-packages\nbclient\util.py", line 84, in wrapped
    return just_run(coro(*args, **kwargs))
           ^^^^^^^^^^^^^^^^^^^^^^^^^^^^^^^
  File "C:\Users\AhmadYazidMunif\AppData\Local\Programs\Python\Python311\Lib\site-packages\nbclient\util.py", line 62, in just_run
    return loop.run_until_complete(coro)
           ^^^^^^^^^^^^^^^^^^^^^^^^^^^^^
  File "C:\Users\AhmadYazidMunif\AppData\Local\Programs\Python\Python311\Lib\asyncio\base_events.py", line 650, in run_until_complete
    return future.result()
           ^^^^^^^^^^^^^^^
  File "C:\Users\AhmadYazidMunif\AppData\Local\Programs\Python\Python311\Lib\contextlib.py", line 222, in __aexit__
    await self.gen.athrow(typ, value, traceback)
  File "C:\Users\AhmadYazidMunif\AppData\Local\Programs\Python\Python311\Lib\site-packages\nbclient\client.py", line 608, in async_setup_kernel
    yield
  File "C:\Users\AhmadYazidMunif\AppData\Local\Programs\Python\Python311\Lib\site-packages\nbclient\client.py", line 663, in async_execute
    await self.async_execute_cell(
  File "C:\Users\AhmadYazidMunif\AppData\Local\Programs\Python\Python311\Lib\site-packages\nbclient\client.py", line 965, in async_execute_cell
    await self._check_raise_for_error(cell, cell_index, exec_reply)
  File "C:\Users\AhmadYazidMunif\AppData\Local\Programs\Python\Python311\Lib\site-packages\nbclient\client.py", line 862, in _check_raise_for_error
    raise CellExecutionError.from_cell_and_msg(cell, exec_reply_content)
nbclient.exceptions.CellExecutionError: An error occurred while executing the following cell:
------------------
dataframe['Publisher'].value_counts()[:10].plot(kind='bar', title='Game Sales:\nMost Frequent "Publisher"')
------------------

[1;31m---------------------------------------------------------------------------[0m
[1;31mKeyError[0m                                  Traceback (most recent call last)
[1;32m~\AppData\Local\Programs\Python\Python311\Lib\site-packages\pandas\core\indexes\base.py[0m in [0;36mget_loc[1;34m(self, key, method, tolerance)[0m
[0;32m   3801[0m             [1;32mtry[0m[1;33m:[0m[1;33m[0m[1;33m[0m[0m
[1;32m-> 3802[1;33m                 [1;32mreturn[0m [0mself[0m[1;33m.[0m[0m_engine[0m[1;33m.[0m[0mget_loc[0m[1;33m([0m[0mcasted_key[0m[1;33m)[0m[1;33m[0m[1;33m[0m[0m
[0m[0;32m   3803[0m             [1;32mexcept[0m [0mKeyError[0m [1;32mas[0m [0merr[0m[1;33m:[0m[1;33m[0m[1;33m[0m[0m

[1;32m~\AppData\Local\Programs\Python\Python311\Lib\site-packages\pandas\_libs\index.pyx[0m in [0;36mpandas._libs.index.IndexEngine.get_loc[1;34m()[0m

[1;32m~\AppData\Local\Programs\Python\Python311\Lib\site-packages\pandas\_libs\index.pyx[0m in [0;36mpandas._libs.index.IndexEngine.get_loc[1;34m()[0m

[1;32mpandas\_libs\hashtable_class_helper.pxi[0m in [0;36mpandas._libs.hashtable.PyObjectHashTable.get_item[1;34m()[0m

[1;32mpandas\_libs\hashtable_class_helper.pxi[0m in [0;36mpandas._libs.hashtable.PyObjectHashTable.get_item[1;34m()[0m

[1;31mKeyError[0m: 'Publisher'

The above exception was the direct cause of the following exception:

[1;31mKeyError[0m                                  Traceback (most recent call last)
[1;32m~\AppData\Local\Temp\ipykernel_16644\1727840546.py[0m in [0;36m<cell line: 0>[1;34m()[0m
[1;32m----> 1[1;33m [0mdataframe[0m[1;33m[[0m[1;34m'Publisher'[0m[1;33m][0m[1;33m.[0m[0mvalue_counts[0m[1;33m([0m[1;33m)[0m[1;33m[[0m[1;33m:[0m[1;36m10[0m[1;33m][0m[1;33m.[0m[0mplot[0m[1;33m([0m[0mkind[0m[1;33m=[0m[1;34m'bar'[0m[1;33m,[0m [0mtitle[0m[1;33m=[0m[1;34m'Game Sales:\nMost Frequent "Publisher"'[0m[1;33m)[0m[1;33m[0m[1;33m[0m[0m
[0m
[1;32m~\AppData\Local\Programs\Python\Python311\Lib\site-packages\pandas\core\frame.py[0m in [0;36m__getitem__[1;34m(self, key)[0m
[0;32m   3805[0m             [1;32mif[0m [0mself[0m[1;33m.[0m[0mcolumns[0m[1;33m.[0m[0mnlevels[0m [1;33m>[0m [1;36m1[0m[1;33m:[0m[1;33m[0m[1;33m[0m[0m
[0;32m   3806[0m                 [1;32mreturn[0m [0mself[0m[1;33m.[0m[0m_getitem_multilevel[0m[1;33m([0m[0mkey[0m[1;33m)[0m[1;33m[0m[1;33m[0m[0m
[1;32m-> 3807[1;33m             [0mindexer[0m [1;33m=[0m [0mself[0m[1;33m.[0m[0mcolumns[0m[1;33m.[0m[0mget_loc[0m[1;33m([0m[0mkey[0m[1;33m)[0m[1;33m[0m[1;33m[0m[0m
[0m[0;32m   3808[0m             [1;32mif[0m [0mis_integer[0m[1;33m([0m[0mindexer[0m[1;33m)[0m[1;33m:[0m[1;33m[0m[1;33m[0m[0m
[0;32m   3809[0m                 [0mindexer[0m [1;33m=[0m [1;33m[[0m[0mindexer[0m[1;33m][0m[1;33m[0m[1;33m[0m[0m

[1;32m~\AppData\Local\Programs\Python\Python311\Lib\site-packages\pandas\core\indexes\base.py[0m in [0;36mget_loc[1;34m(self, key, method, tolerance)[0m
[0;32m   3802[0m                 [1;32mreturn[0m [0mself[0m[1;33m.[0m[0m_engine[0m[1;33m.[0m[0mget_loc[0m[1;33m([0m[0mcasted_key[0m[1;33m)[0m[1;33m[0m[1;33m[0m[0m
[0;32m   3803[0m             [1;32mexcept[0m [0mKeyError[0m [1;32mas[0m [0merr[0m[1;33m:[0m[1;33m[0m[1;33m[0m[0m
[1;32m-> 3804[1;33m                 [1;32mraise[0m [0mKeyError[0m[1;33m([0m[0mkey[0m[1;33m)[0m [1;32mfrom[0m [0merr[0m[1;33m[0m[1;33m[0m[0m
[0m[0;32m   3805[0m             [1;32mexcept[0m [0mTypeError[0m[1;33m:[0m[1;33m[0m[1;33m[0m[0m
[0;32m   3806[0m                 [1;31m# If we have a listlike key, _check_indexing_error will raise[0m[1;33m[0m[1;33m[0m[0m

[1;31mKeyError[0m: 'Publisher'
KeyError: 'Publisher'

